<mujoco model="fr3">
  <compiler angle="radian" meshdir="../assets"/>

  <default>
    <default class="fr3">
      <joint armature="0.1" damping="1"/>
      <position inheritrange="1"/>
      <default class="visual">
        <geom type="mesh" group="2" contype="0" conaffinity="0"/>
      </default>
      <site size="0.001" rgba="0.5 0.5 0.5 0.3" group="4"/>

      <default class="probe">
        <joint axis="0 0 1" type="slide" range="0 0.001"/>
      </default>
      <default class="collision">
        <geom type="mesh" group="3"/>
      </default>
    </default>
  </default>

  <contact>
    <exclude body1="fr3_link5" body2="fr3_link6"/>
    <exclude body1="fr3_link5" body2="fr3_link7"/>
    <exclude body1="fr3_link6" body2="fr3_link7"/>
    <exclude body1="fr3_link6" body2="probe"/>
    <exclude body1="fr3_link7" body2="probe"/>
    <exclude body1="fr3_link5" body2="probe"/>
  </contact>


  <asset>
    <material name="black" rgba=".2 .2 .2 1"/>
    <material name="white" rgba="1 1 1 1"/>
    <material name="off_white" rgba="0.901961 0.921569 0.929412 1"/>
    <material name="red" rgba="1 0.072272 0.039546 1"/>
    <material name="gray" rgba="0.863156 0.863156 0.863157 1"/>
    <material name="button_green" rgba="0.102241 0.571125 0.102242 1"/>
    <material name="button_red" rgba="0.520996 0.008023 0.013702 1"/>
    <material name="button_blue" rgba="0.024157 0.445201 0.737911 1"/>

    <mesh file="link0_0.obj"/>
    <mesh file="link0_1.obj"/>
    <mesh file="link0_2.obj"/>
    <mesh file="link0_3.obj"/>
    <mesh file="link0_4.obj"/>
    <mesh file="link0_5.obj"/>
    <mesh file="link0_6.obj"/>
    <mesh file="link1.obj"/>
    <mesh file="link2.obj"/>
    <mesh file="link3_0.obj"/>
    <mesh file="link3_1.obj"/>
    <mesh file="link4_0.obj"/>
    <mesh file="link4_1.obj"/>
    <mesh file="link5_0.obj"/>
    <mesh file="link5_1.obj"/>
    <mesh file="link5_2.obj"/>
    <mesh file="link6_0.obj"/>
    <mesh file="link6_1.obj"/>
    <mesh file="link6_2.obj"/>
    <mesh file="link6_3.obj"/>
    <mesh file="link6_4.obj"/>
    <mesh file="link6_5.obj"/>
    <mesh file="link6_6.obj"/>
    <mesh file="link6_7.obj"/>
    <mesh file="link7_0.obj"/>
    <mesh file="link7_1.obj"/>
    <mesh file="link7_2.obj"/>
    <mesh file="link7_3.obj"/>

    <mesh name="link0_coll" file="link0.stl"/>
    <mesh name="link1_coll" file="link1.stl"/>
    <mesh name="link2_coll" file="link2.stl"/>
    <mesh name="link3_coll" file="link3.stl"/>
    <mesh name="link4_coll" file="link4.stl"/>
    <mesh name="link5_coll" file="link5.stl"/>
    <mesh name="link6_coll" file="link6.stl"/>
    <mesh name="link7_coll" file="link7.stl"/>

    <mesh name="probe_coll" file="ultrasound_probe.stl"/>
  </asset>

  <worldbody>
    <body name="base" childclass="fr3">
      <body name="fr3_link0">
        <geom mesh="link0_0" material="black" class="visual"/>
        <geom mesh="link0_1" material="white" class="visual"/>
        <geom mesh="link0_2" material="white" class="visual"/>
        <geom mesh="link0_3" material="white" class="visual"/>
        <geom mesh="link0_4" material="white" class="visual"/>
        <geom mesh="link0_5" material="red" class="visual"/>
        <geom mesh="link0_6" material="black" class="visual"/>
        <geom name="fr3_link0_collision" mesh="link0_coll" class="collision"/>
        <body name="fr3_link1" pos="0 0 0.333">
          <inertial pos="4.128e-07 -0.0181251 -0.0386036" quat="0.999901 0.0021545 0.00429041 0.0132325" mass="2.92747"
            diaginertia="0.0186043 0.0181194 0.00538716"/>
          <joint name="fr3_joint1" axis="0 0 1" range="-2.7437 2.7437" actuatorfrcrange="-87 87"/>
          <geom name="fr3_link1_collision" class="collision" mesh="link1_coll"/>
          <geom material="white" mesh="link1" class="visual"/>
          <body name="fr3_link2" quat="1 -1 0 0">
            <inertial pos="0.00318289 -0.0743222 0.00881461" quat="0.356855 0.680818 -0.434812 0.469126" mass="2.93554"
              diaginertia="0.0299291 0.0299291 0.0299291"/>
            <joint name="fr3_joint2" axis="0 0 1" range="-1.7837 1.7837" actuatorfrcrange="-87 87"/>
            <geom material="white" mesh="link2" class="visual"/>
            <geom name="fr3_link2_collision" class="collision" mesh="link2_coll"/>
            <body name="fr3_link3" pos="0 -0.316 0" quat="1 1 0 0">
              <inertial pos="0.0407016 -0.00482006 -0.0289731" quat="0.950032 -0.148357 0.229935 0.150201" mass="2.2449"
                diaginertia="0.0140109 0.0140109 0.0140109"/>
              <joint name="fr3_joint3" axis="0 0 1" range="-2.9007 2.9007" actuatorfrcrange="-87 87"/>
              <geom mesh="link3_0" material="white" class="visual"/>
              <geom mesh="link3_1" material="black" class="visual"/>
              <geom name="fr3_link3_collision" class="collision" mesh="link3_coll"/>
              <body name="fr3_link4" pos="0.0825 0 0" quat="1 1 0 0">
                <inertial pos="-0.0459101 0.0630493 -0.00851879" quat="0.23761 0.892458 -0.00078702 0.383484"
                  mass="2.6156" diaginertia="0.0206104 0.0206104 0.0206104"/>
                <joint name="fr3_joint4" axis="0 0 1" range="-3.0421 -0.1518" actuatorfrcrange="-87 87"/>
                <geom mesh="link4_0" material="white" class="visual"/>
                <geom mesh="link4_1" material="black" class="visual"/>
                <geom name="fr3_link4_collision" class="collision" mesh="link4_coll"/>
                <body name="fr3_link5" pos="-0.0825 0.384 0" quat="1 -1 0 0">
                  <inertial pos="-0.00160396 0.0292536 -0.0972966" quat="0.922285 0.098826 0.0982562 -0.360514"
                    mass="2.32712" diaginertia="0.0182879 0.0182879 0.0182879"/>
                  <joint name="fr3_joint5" axis="0 0 1" range="-2.8065 2.8065" actuatorfrcrange="-12 12"/>
                  <geom mesh="link5_0" material="white" class="visual"/>
                  <geom mesh="link5_1" material="white" class="visual"/>
                  <geom mesh="link5_2" material="black" class="visual"/>
                  <geom name="fr3_link5_collision" class="collision" mesh="link5_coll"/>
                  <body name="fr3_link6" quat="1 1 0 0">
                    <inertial pos="0.0597131 -0.0410295 -0.0101693" quat="0.593933 0.525442 0.520644 0.316361"
                      mass="1.81704" diaginertia="0.00483538 0.00483538 0.00483538"/>
                    <joint name="fr3_joint6" axis="0 0 1" range="0.5445 4.5169" actuatorfrcrange="-12 12"/>
                    <geom mesh="link6_0" material="button_green" class="visual"/>
                    <geom mesh="link6_1" material="white" class="visual"/>
                    <geom mesh="link6_2" material="white" class="visual"/>
                    <geom mesh="link6_3" material="gray" class="visual"/>
                    <geom mesh="link6_4" material="button_red" class="visual"/>
                    <geom mesh="link6_5" material="white" class="visual"/>
                    <geom mesh="link6_6" material="black" class="visual"/>
                    <geom mesh="link6_7" material="button_blue" class="visual"/>
                    <geom name="fr3_link6_collision" class="collision" mesh="link6_coll"/>
                    <body name="fr3_link7" pos="0.088 0 0" quat="1 1 0 0">
                      <inertial pos="0.00452258 0.00862619 -0.0161633" quat="0.120255 0.394761 -0.799132 0.437139"
                        mass="0.627143" diaginertia="3.076e-07 3.076e-07 3.076e-07"/>
                      <joint name="fr3_joint7" axis="0 0 1" range="-3.0159 3.0159" actuatorfrcrange="-12 12"/>
                      <geom mesh="link7_0" material="black" class="visual"/>
                      <geom mesh="link7_1" material="white" class="visual"/>
                      <geom mesh="link7_2" material="white" class="visual"/>
                      <geom mesh="link7_3" material="black" class="visual"/>
                      <geom name="fr3_link7_collision" class="collision" mesh="link7_coll"/>

                      <body name="probe" pos="0 0 0.155" quat="0.9238795 0 0 -0.3826834">
                        <joint name="probe_slide" type="slide" range="0.0 0.001"/>
                        <inertial mass="0.73" pos="-0.01 0 0.03" diaginertia="0.001 0.0025 0.0017"/>
                        <geom mesh="probe_coll" material="off_white" class="visual"/>
                        <geom mesh="probe_coll" class="collision"/>

                        <site name="probeEE" pos="0.0 0 0.0" rgba="1 0 0 1"/>
                        <geom name="EE" type="sphere" size="0.005" pos="0 0 0.0" rgba="1 1 0 1" />
                        <geom type="cylinder" size="0.002 0.03" rgba="1 0 0 1" pos="0.03 0 0.035" euler="0 1.57079 0" contype="0" conaffinity="0" mass="0"/>  
                        <geom type="cylinder" size="0.002 0.03" rgba="0 1 0 1" pos="0 0.03 0.035" euler="1.57079 0 0" contype="0" conaffinity="0" mass="0"/>  
                        <geom type="cylinder" size="0.002 0.03" rgba="0 0 1 1" pos="0 0 0.065" euler="0 0 0" contype="0" conaffinity="0" mass="0"/>
                      </body>

                    </body>
                  </body>
                </body>
              </body>
            </body>
          </body>
        </body>
      </body>
    </body>
  </worldbody>

  <actuator>
    <motor class="fr3" name="lj1" joint="fr3_joint1"/>
    <motor class="fr3" name="lj2" joint="fr3_joint2"/>
    <motor class="fr3" name="lj3" joint="fr3_joint3"/>
    <motor class="fr3" name="lj4" joint="fr3_joint4"/>
    <motor class="fr3" name="lj5" joint="fr3_joint5"/>
    <motor class="fr3" name="lj6" joint="fr3_joint6"/>
    <motor class="fr3" name="lj7" joint="fr3_joint7"/>
    <general class="fr3" name="lj8" joint="probe_slide" forcerange="-100 100" ctrlrange="0 255"
      gainprm="0.01568627451 0 0" biasprm="0 -100 -10"/>
  </actuator>

  <sensor>
    <framepos name="eePos" objtype="site" objname="probeEE"/>
    <framequat name="eeQuat" objtype="site" objname="probeEE"/>
    <framelinvel name="eeLinVel" objtype="site" objname="probeEE"/>
    <frameangvel name="eeAngVel" objtype="site" objname="probeEE"/>
    <gyro name="eeGyro" site="probeEE"/>
    <accelerometer name="eeAcc" site="probeEE"/>
    <force name="eeForce" site="probeEE"/>
	</sensor>
</mujoco>
